Workbook
Name Quota: Inputs!$C$5
Name CovTarget: Inputs!$C$7
Name GPTarget: Inputs!$C$9
Name AgeThresh: Inputs!$C$11
Name RiskThresh: Inputs!$C$13
Name DashTitle: Inputs!$C$15
Name DashSub: Inputs!$C$17
Name RepPrefix1: Inputs!$C$22
Name RepName1: Inputs!$C$23
Name RepPrefix2: Inputs!$C$25
Name RepName2: Inputs!$C$26
Name RepPrefix3: Inputs!$C$28
Name RepName3: Inputs!$C$29
Name RepPrefix4: Inputs!$C$31
Name RepName4: Inputs!$C$32
Name RepPrefix5: Inputs!$C$34
Name RepName5: Inputs!$C$35
Name RepPrefix6: Inputs!$C$37
Name RepName6: Inputs!$C$38

Sheet Dashboard
B2: =DashTitle | H2: =UPPER(TEXT(TODAY(),"DDDD, DD MMMM YYYY"))
B3: =DashSub | H3: =RepName1&" · "&RepName2&" · "&RepName3
B5: ='Per-Rep Detail'!H11 | D5: ='Per-Rep Detail'!I11 | F5: =IFERROR('Per-Rep Detail'!I11/'Per-Rep Detail'!H11,0) | H5: ='Per-Rep Detail'!K11 | J5: ='Per-Rep Detail'!D11 | L5: ='Per-Rep Detail'!G11
B6: TOTAL TCV | D6: TOTAL GP | F6: GP MARGIN | H6: WEIGHTED PIPE | J6: ACTIVE OPPS | L6: WIN RATE
B8: REP LEADERBOARD | H8: STAGE BREAKDOWN
B9: REP | C9: TCV | D9: GP | E9: GP% | F9: WTD PIPE | H9: STAGE | I9: OPPS | J9: TCV | K9: WTD | L9: PROB | N9: Δ vs Quota
B10: =RepName3 | C10: =(SUMIFS('Home-Conversion'!H4:H202,'Home-Conversion'!G4:G202,"<>Closed Lost",'Home-Conversion'!G4:G202,"<>")) | D10: =(SUMIFS('Home-Conversion'!I4:I202,'Home-Conversion'!G4:G202,"<>Closed Lost",'Home-Conversion'!G4:G202,"<>")) | E10: =IFERROR((SUMIFS('Home-Conversion'!I4:I202,'Home-Conversion'!G4:G202,"<>Closed Lost",'Home-Conversion'!G4:G202,"<>"))/(SUMIFS('Home-Conversion'!H4:H202,'Home-Conversion'!G4:G202,"<>Closed Lost",'Home-Conversion'!G4:G202,"<>")),0) | F10: =((SUMIFS('Home-Conversion'!H4:H202,'Home-Conversion'!G4:G202,"Opportunity Creation")*0.1+SUMIFS('Home-Conversion'!H4:H202,'Home-Conversion'!G4:G202,"Scoping")*0.3+SUMIFS('Home-Conversion'!H4:H202,'Home-Conversion'!G4:G202,"BOM Submission")*0.5+SUMIFS('Home-Conversion'!H4:H202,'Home-Conversion'!G4:G202,"Resubmission")*0.7+SUMIFS('Home-Conversion'!H4:H202,'Home-Conversion'!G4:G202,"Negotiation")*0.9)) | H10: Opportunity Creation | I10: =COUNTIF('Madine- Conversion'!G4:G202,"Opportunity Creation")+COUNTIF('Zarrah-Conversion'!G3:G201,"Opportunity Creation")+COUNTIF('Home-Conversion'!G4:G202,"Opportunity Creation")+IF(RepPrefix4="",0,IFERROR(COUNTIF(INDIRECT("'"&RepPrefix4&"- Conversion'!G4:G202"),"Opportunity Creation"),0))+IF(RepPrefix5="",0,IFERROR(COUNTIF(INDIRECT("'"&RepPrefix5&"- Conversion'!G4:G202"),"Opportunity Creation"),0))+IF(RepPrefix6="",0,IFERROR(COUNTIF(INDIRECT("'"&RepPrefix6&"- Conversion'!G4:G202"),"Opportunity Creation"),0)) | J10: =SUMIFS('Madine- Conversion'!H4:H202,'Madine- Conversion'!G4:G202,"Opportunity Creation")+SUMIFS('Zarrah-Conversion'!H3:H201,'Zarrah-Conversion'!G3:G201,"Opportunity Creation")+SUMIFS('Home-Conversion'!H4:H202,'Home-Conversion'!G4:G202,"Opportunity Creation")+IF(RepPrefix4="",0,IFERROR(SUMIFS(INDIRECT("'"&RepPrefix4&"- Conversion'!H4:H202"),INDIRECT("'"&RepPrefix4&"- Conversion'!G4:G202"),"Opportunity Creation"),0))+IF(RepPrefix5="",0,IFERROR(SUMIFS(INDIRECT("'"&RepPrefix5&"- Conversion'!H4:H202"),INDIRECT("'"&RepPrefix5&"- Conversion'!G4:G202"),"Opportunity Creation"),0))+IF(RepPrefix6="",0,IFERROR(SUMIFS(INDIRECT("'"&RepPrefix6&"- Conversion'!H4:H202"),INDIRECT("'"&RepPrefix6&"- Conversion'!G4:G202"),"Opportunity Creation"),0)) | K10: =J10*0.1 | L10: 0.1 | N10: =IFERROR(F16/Quota,0)
B11: =RepName2 | C11: =(SUMIFS('Zarrah-Conversion'!H3:H201,'Zarrah-Conversion'!G3:G201,"<>Closed Lost",'Zarrah-Conversion'!G3:G201,"<>")) | D11: =(SUMIFS('Zarrah-Conversion'!I3:I201,'Zarrah-Conversion'!G3:G201,"<>Closed Lost",'Zarrah-Conversion'!G3:G201,"<>")) | E11: =IFERROR((SUMIFS('Zarrah-Conversion'!I3:I201,'Zarrah-Conversion'!G3:G201,"<>Closed Lost",'Zarrah-Conversion'!G3:G201,"<>"))/(SUMIFS('Zarrah-Conversion'!H3:H201,'Zarrah-Conversion'!G3:G201,"<>Closed Lost",'Zarrah-Conversion'!G3:G201,"<>")),0) | F11: =((SUMIFS('Zarrah-Conversion'!H3:H201,'Zarrah-Conversion'!G3:G201,"Opportunity Creation")*0.1+SUMIFS('Zarrah-Conversion'!H3:H201,'Zarrah-Conversion'!G3:G201,"Scoping")*0.3+SUMIFS('Zarrah-Conversion'!H3:H201,'Zarrah-Conversion'!G3:G201,"BOM Submission")*0.5+SUMIFS('Zarrah-Conversion'!H3:H201,'Zarrah-Conversion'!G3:G201,"Resubmission")*0.7+SUMIFS('Zarrah-Conversion'!H3:H201,'Zarrah-Conversion'!G3:G201,"Negotiation")*0.9)) | H11: Scoping | I11: =COUNTIF('Madine- Conversion'!G4:G202,"Scoping")+COUNTIF('Zarrah-Conversion'!G3:G201,"Scoping")+COUNTIF('Home-Conversion'!G4:G202,"Scoping")+IF(RepPrefix4="",0,IFERROR(COUNTIF(INDIRECT("'"&RepPrefix4&"- Conversion'!G4:G202"),"Scoping"),0))+IF(RepPrefix5="",0,IFERROR(COUNTIF(INDIRECT("'"&RepPrefix5&"- Conversion'!G4:G202"),"Scoping"),0))+IF(RepPrefix6="",0,IFERROR(COUNTIF(INDIRECT("'"&RepPrefix6&"- Conversion'!G4:G202"),"Scoping"),0)) | J11: =SUMIFS('Madine- Conversion'!H4:H202,'Madine- Conversion'!G4:G202,"Scoping")+SUMIFS('Zarrah-Conversion'!H3:H201,'Zarrah-Conversion'!G3:G201,"Scoping")+SUMIFS('Home-Conversion'!H4:H202,'Home-Conversion'!G4:G202,"Scoping")+IF(RepPrefix4="",0,IFERROR(SUMIFS(INDIRECT("'"&RepPrefix4&"- Conversion'!H4:H202"),INDIRECT("'"&RepPrefix4&"- Conversion'!G4:G202"),"Scoping"),0))+IF(RepPrefix5="",0,IFERROR(SUMIFS(INDIRECT("'"&RepPrefix5&"- Conversion'!H4:H202"),INDIRECT("'"&RepPrefix5&"- Conversion'!G4:G202"),"Scoping"),0))+IF(RepPrefix6="",0,IFERROR(SUMIFS(INDIRECT("'"&RepPrefix6&"- Conversion'!H4:H202"),INDIRECT("'"&RepPrefix6&"- Conversion'!G4:G202"),"Scoping"),0)) | K11: =J11*0.3 | L11: 0.3 | N11: Pipe÷Quota
B12: =RepName1 | C12: =(SUMIFS('Madine- Conversion'!H4:H202,'Madine- Conversion'!G4:G202,"<>Closed Lost",'Madine- Conversion'!G4:G202,"<>")) | D12: =(SUMIFS('Madine- Conversion'!I4:I202,'Madine- Conversion'!G4:G202,"<>Closed Lost",'Madine- Conversion'!G4:G202,"<>")) | E12: =IFERROR((SUMIFS('Madine- Conversion'!I4:I202,'Madine- Conversion'!G4:G202,"<>Closed Lost",'Madine- Conversion'!G4:G202,"<>"))/(SUMIFS('Madine- Conversion'!H4:H202,'Madine- Conversion'!G4:G202,"<>Closed Lost",'Madine- Conversion'!G4:G202,"<>")),0) | F12: =((SUMIFS('Madine- Conversion'!H4:H202,'Madine- Conversion'!G4:G202,"Opportunity Creation")*0.1+SUMIFS('Madine- Conversion'!H4:H202,'Madine- Conversion'!G4:G202,"Scoping")*0.3+SUMIFS('Madine- Conversion'!H4:H202,'Madine- Conversion'!G4:G202,"BOM Submission")*0.5+SUMIFS('Madine- Conversion'!H4:H202,'Madine- Conversion'!G4:G202,"Resubmission")*0.7+SUMIFS('Madine- Conversion'!H4:H202,'Madine- Conversion'!G4:G202,"Negotiation")*0.9)) | H12: BOM Submission | I12: =COUNTIF('Madine- Conversion'!G4:G202,"BOM Submission")+COUNTIF('Zarrah-Conversion'!G3:G201,"BOM Submission")+COUNTIF('Home-Conversion'!G4:G202,"BOM Submission")+IF(RepPrefix4="",0,IFERROR(COUNTIF(INDIRECT("'"&RepPrefix4&"- Conversion'!G4:G202"),"BOM Submission"),0))+IF(RepPrefix5="",0,IFERROR(COUNTIF(INDIRECT("'"&RepPrefix5&"- Conversion'!G4:G202"),"BOM Submission"),0))+IF(RepPrefix6="",0,IFERROR(COUNTIF(INDIRECT("'"&RepPrefix6&"- Conversion'!G4:G202"),"BOM Submission"),0)) | J12: =SUMIFS('Madine- Conversion'!H4:H202,'Madine- Conversion'!G4:G202,"BOM Submission")+SUMIFS('Zarrah-Conversion'!H3:H201,'Zarrah-Conversion'!G3:G201,"BOM Submission")+SUMIFS('Home-Conversion'!H4:H202,'Home-Conversion'!G4:G202,"BOM Submission")+IF(RepPrefix4="",0,IFERROR(SUMIFS(INDIRECT("'"&RepPrefix4&"- Conversion'!H4:H202"),INDIRECT("'"&RepPrefix4&"- Conversion'!G4:G202"),"BOM Submission"),0))+IF(RepPrefix5="",0,IFERROR(SUMIFS(INDIRECT("'"&RepPrefix5&"- Conversion'!H4:H202"),INDIRECT("'"&RepPrefix5&"- Conversion'!G4:G202"),"BOM Submission"),0))+IF(RepPrefix6="",0,IFERROR(SUMIFS(INDIRECT("'"&RepPrefix6&"- Conversion'!H4:H202"),INDIRECT("'"&RepPrefix6&"- Conversion'!G4:G202"),"BOM Submission"),0)) | K12: =J12*0.5 | L12: 0.5
B13: =IF(RepPrefix4="","",RepName4) | C13: =IF(RepPrefix4="","",(IF(RepPrefix4="",0,IFERROR(SUMIFS(INDIRECT("'"&RepPrefix4&"- Conversion'!H4:H202"),INDIRECT("'"&RepPrefix4&"- Conversion'!G4:G202"),"<>Closed Lost",INDIRECT("'"&RepPrefix4&"- Conversion'!G4:G202"),"<>"),0)))) | D13: =IF(RepPrefix4="","",(IF(RepPrefix4="",0,IFERROR(SUMIFS(INDIRECT("'"&RepPrefix4&"- Conversion'!I4:I202"),INDIRECT("'"&RepPrefix4&"- Conversion'!G4:G202"),"<>Closed Lost",INDIRECT("'"&RepPrefix4&"- Conversion'!G4:G202"),"<>"),0)))) | E13: =IF(RepPrefix4="","",IFERROR((IF(RepPrefix4="",0,IFERROR(SUMIFS(INDIRECT("'"&RepPrefix4&"- Conversion'!I4:I202"),INDIRECT("'"&RepPrefix4&"- Conversion'!G4:G202"),"<>Closed Lost",INDIRECT("'"&RepPrefix4&"- Conversion'!G4:G202"),"<>"),0)))/(IF(RepPrefix4="",0,IFERROR(SUMIFS(INDIRECT("'"&RepPrefix4&"- Conversion'!H4:H202"),INDIRECT("'"&RepPrefix4&"- Conversion'!G4:G202"),"<>Closed Lost",INDIRECT("'"&RepPrefix4&"- Conversion'!G4:G202"),"<>"),0))),0)) | F13: =IF(RepPrefix4="","",((IF(RepPrefix4="",0,IFERROR(SUMIFS(INDIRECT("'"&RepPrefix4&"- Conversion'!H4:H202"),INDIRECT("'"&RepPrefix4&"- Conversion'!G4:G202"),"Opportunity Creation"),0))*0.1+IF(RepPrefix4="",0,IFERROR(SUMIFS(INDIRECT("'"&RepPrefix4&"- Conversion'!H4:H202"),INDIRECT("'"&RepPrefix4&"- Conversion'!G4:G202"),"Scoping"),0))*0.3+IF(RepPrefix4="",0,IFERROR(SUMIFS(INDIRECT("'"&RepPrefix4&"- Conversion'!H4:H202"),INDIRECT("'"&RepPrefix4&"- Conversion'!G4:G202"),"BOM Submission"),0))*0.5+IF(RepPrefix4="",0,IFERROR(SUMIFS(INDIRECT("'"&RepPrefix4&"- Conversion'!H4:H202"),INDIRECT("'"&RepPrefix4&"- Conversion'!G4:G202"),"Resubmission"),0))*0.7+IF(RepPrefix4="",0,IFERROR(SUMIFS(INDIRECT("'"&RepPrefix4&"- Conversion'!H4:H202"),INDIRECT("'"&RepPrefix4&"- Conversion'!G4:G202"),"Negotiation"),0))*0.9))) | H13: Resubmission | I13: =COUNTIF('Madine- Conversion'!G4:G202,"Resubmission")+COUNTIF('Zarrah-Conversion'!G3:G201,"Resubmission")+COUNTIF('Home-Conversion'!G4:G202,"Resubmission")+IF(RepPrefix4="",0,IFERROR(COUNTIF(INDIRECT("'"&RepPrefix4&"- Conversion'!G4:G202"),"Resubmission"),0))+IF(RepPrefix5="",0,IFERROR(COUNTIF(INDIRECT("'"&RepPrefix5&"- Conversion'!G4:G202"),"Resubmission"),0))+IF(RepPrefix6="",0,IFERROR(COUNTIF(INDIRECT("'"&RepPrefix6&"- Conversion'!G4:G202"),"Resubmission"),0)) | J13: =SUMIFS('Madine- Conversion'!H4:H202,'Madine- Conversion'!G4:G202,"Resubmission")+SUMIFS('Zarrah-Conversion'!H3:H201,'Zarrah-Conversion'!G3:G201,"Resubmission")+SUMIFS('Home-Conversion'!H4:H202,'Home-Conversion'!G4:G202,"Resubmission")+IF(RepPrefix4="",0,IFERROR(SUMIFS(INDIRECT("'"&RepPrefix4&"- Conversion'!H4:H202"),INDIRECT("'"&RepPrefix4&"- Conversion'!G4:G202"),"Resubmission"),0))+IF(RepPrefix5="",0,IFERROR(SUMIFS(INDIRECT("'"&RepPrefix5&"- Conversion'!H4:H202"),INDIRECT("'"&RepPrefix5&"- Conversion'!G4:G202"),"Resubmission"),0))+IF(RepPrefix6="",0,IFERROR(SUMIFS(INDIRECT("'"&RepPrefix6&"- Conversion'!H4:H202"),INDIRECT("'"&RepPrefix6&"- Conversion'!G4:G202"),"Resubmission"),0)) | K13: =J13*0.7 | L13: 0.7
B14: =IF(RepPrefix5="","",RepName5) | C14: =IF(RepPrefix5="","",(IF(RepPrefix5="",0,IFERROR(SUMIFS(INDIRECT("'"&RepPrefix5&"- Conversion'!H4:H202"),INDIRECT("'"&RepPrefix5&"- Conversion'!G4:G202"),"<>Closed Lost",INDIRECT("'"&RepPrefix5&"- Conversion'!G4:G202"),"<>"),0)))) | D14: =IF(RepPrefix5="","",(IF(RepPrefix5="",0,IFERROR(SUMIFS(INDIRECT("'"&RepPrefix5&"- Conversion'!I4:I202"),INDIRECT("'"&RepPrefix5&"- Conversion'!G4:G202"),"<>Closed Lost",INDIRECT("'"&RepPrefix5&"- Conversion'!G4:G202"),"<>"),0)))) | E14: =IF(RepPrefix5="","",IFERROR((IF(RepPrefix5="",0,IFERROR(SUMIFS(INDIRECT("'"&RepPrefix5&"- Conversion'!I4:I202"),INDIRECT("'"&RepPrefix5&"- Conversion'!G4:G202"),"<>Closed Lost",INDIRECT("'"&RepPrefix5&"- Conversion'!G4:G202"),"<>"),0)))/(IF(RepPrefix5="",0,IFERROR(SUMIFS(INDIRECT("'"&RepPrefix5&"- Conversion'!H4:H202"),INDIRECT("'"&RepPrefix5&"- Conversion'!G4:G202"),"<>Closed Lost",INDIRECT("'"&RepPrefix5&"- Conversion'!G4:G202"),"<>"),0))),0)) | F14: =IF(RepPrefix5="","",((IF(RepPrefix5="",0,IFERROR(SUMIFS(INDIRECT("'"&RepPrefix5&"- Conversion'!H4:H202"),INDIRECT("'"&RepPrefix5&"- Conversion'!G4:G202"),"Opportunity Creation"),0))*0.1+IF(RepPrefix5="",0,IFERROR(SUMIFS(INDIRECT("'"&RepPrefix5&"- Conversion'!H4:H202"),INDIRECT("'"&RepPrefix5&"- Conversion'!G4:G202"),"Scoping"),0))*0.3+IF(RepPrefix5="",0,IFERROR(SUMIFS(INDIRECT("'"&RepPrefix5&"- Conversion'!H4:H202"),INDIRECT("'"&RepPrefix5&"- Conversion'!G4:G202"),"BOM Submission"),0))*0.5+IF(RepPrefix5="",0,IFERROR(SUMIFS(INDIRECT("'"&RepPrefix5&"- Conversion'!H4:H202"),INDIRECT("'"&RepPrefix5&"- Conversion'!G4:G202"),"Resubmission"),0))*0.7+IF(RepPrefix5="",0,IFERROR(SUMIFS(INDIRECT("'"&RepPrefix5&"- Conversion'!H4:H202"),INDIRECT("'"&RepPrefix5&"- Conversion'!G4:G202"),"Negotiation"),0))*0.9))) | H14: Negotiation | I14: =COUNTIF('Madine- Conversion'!G4:G202,"Negotiation")+COUNTIF('Zarrah-Conversion'!G3:G201,"Negotiation")+COUNTIF('Home-Conversion'!G4:G202,"Negotiation")+IF(RepPrefix4="",0,IFERROR(COUNTIF(INDIRECT("'"&RepPrefix4&"- Conversion'!G4:G202"),"Negotiation"),0))+IF(RepPrefix5="",0,IFERROR(COUNTIF(INDIRECT("'"&RepPrefix5&"- Conversion'!G4:G202"),"Negotiation"),0))+IF(RepPrefix6="",0,IFERROR(COUNTIF(INDIRECT("'"&RepPrefix6&"- Conversion'!G4:G202"),"Negotiation"),0)) | J14: =SUMIFS('Madine- Conversion'!H4:H202,'Madine- Conversion'!G4:G202,"Negotiation")+SUMIFS('Zarrah-Conversion'!H3:H201,'Zarrah-Conversion'!G3:G201,"Negotiation")+SUMIFS('Home-Conversion'!H4:H202,'Home-Conversion'!G4:G202,"Negotiation")+IF(RepPrefix4="",0,IFERROR(SUMIFS(INDIRECT("'"&RepPrefix4&"- Conversion'!H4:H202"),INDIRECT("'"&RepPrefix4&"- Conversion'!G4:G202"),"Negotiation"),0))+IF(RepPrefix5="",0,IFERROR(SUMIFS(INDIRECT("'"&RepPrefix5&"- Conversion'!H4:H202"),INDIRECT("'"&RepPrefix5&"- Conversion'!G4:G202"),"Negotiation"),0))+IF(RepPrefix6="",0,IFERROR(SUMIFS(INDIRECT("'"&RepPrefix6&"- Conversion'!H4:H202"),INDIRECT("'"&RepPrefix6&"- Conversion'!G4:G202"),"Negotiation"),0)) | K14: =J14*0.9 | L14: 0.9
B15: =IF(RepPrefix6="","",RepName6) | C15: =IF(RepPrefix6="","",(IF(RepPrefix6="",0,IFERROR(SUMIFS(INDIRECT("'"&RepPrefix6&"- Conversion'!H4:H202"),INDIRECT("'"&RepPrefix6&"- Conversion'!G4:G202"),"<>Closed Lost",INDIRECT("'"&RepPrefix6&"- Conversion'!G4:G202"),"<>"),0)))) | D15: =IF(RepPrefix6="","",(IF(RepPrefix6="",0,IFERROR(SUMIFS(INDIRECT("'"&RepPrefix6&"- Conversion'!I4:I202"),INDIRECT("'"&RepPrefix6&"- Conversion'!G4:G202"),"<>Closed Lost",INDIRECT("'"&RepPrefix6&"- Conversion'!G4:G202"),"<>"),0)))) | E15: =IF(RepPrefix6="","",IFERROR((IF(RepPrefix6="",0,IFERROR(SUMIFS(INDIRECT("'"&RepPrefix6&"- Conversion'!I4:I202"),INDIRECT("'"&RepPrefix6&"- Conversion'!G4:G202"),"<>Closed Lost",INDIRECT("'"&RepPrefix6&"- Conversion'!G4:G202"),"<>"),0)))/(IF(RepPrefix6="",0,IFERROR(SUMIFS(INDIRECT("'"&RepPrefix6&"- Conversion'!H4:H202"),INDIRECT("'"&RepPrefix6&"- Conversion'!G4:G202"),"<>Closed Lost",INDIRECT("'"&RepPrefix6&"- Conversion'!G4:G202"),"<>"),0))),0)) | F15: =IF(RepPrefix6="","",((IF(RepPrefix6="",0,IFERROR(SUMIFS(INDIRECT("'"&RepPrefix6&"- Conversion'!H4:H202"),INDIRECT("'"&RepPrefix6&"- Conversion'!G4:G202"),"Opportunity Creation"),0))*0.1+IF(RepPrefix6="",0,IFERROR(SUMIFS(INDIRECT("'"&RepPrefix6&"- Conversion'!H4:H202"),INDIRECT("'"&RepPrefix6&"- Conversion'!G4:G202"),"Scoping"),0))*0.3+IF(RepPrefix6="",0,IFERROR(SUMIFS(INDIRECT("'"&RepPrefix6&"- Conversion'!H4:H202"),INDIRECT("'"&RepPrefix6&"- Conversion'!G4:G202"),"BOM Submission"),0))*0.5+IF(RepPrefix6="",0,IFERROR(SUMIFS(INDIRECT("'"&RepPrefix6&"- Conversion'!H4:H202"),INDIRECT("'"&RepPrefix6&"- Conversion'!G4:G202"),"Resubmission"),0))*0.7+IF(RepPrefix6="",0,IFERROR(SUMIFS(INDIRECT("'"&RepPrefix6&"- Conversion'!H4:H202"),INDIRECT("'"&RepPrefix6&"- Conversion'!G4:G202"),"Negotiation"),0))*0.9))) | H15: Closed Won | I15: =COUNTIF('Madine- Conversion'!G4:G202,"Closed Won")+COUNTIF('Zarrah-Conversion'!G3:G201,"Closed Won")+COUNTIF('Home-Conversion'!G4:G202,"Closed Won")+IF(RepPrefix4="",0,IFERROR(COUNTIF(INDIRECT("'"&RepPrefix4&"- Conversion'!G4:G202"),"Closed Won"),0))+IF(RepPrefix5="",0,IFERROR(COUNTIF(INDIRECT("'"&RepPrefix5&"- Conversion'!G4:G202"),"Closed Won"),0))+IF(RepPrefix6="",0,IFERROR(COUNTIF(INDIRECT("'"&RepPrefix6&"- Conversion'!G4:G202"),"Closed Won"),0)) | J15: =SUMIFS('Madine- Conversion'!H4:H202,'Madine- Conversion'!G4:G202,"Closed Won")+SUMIFS('Zarrah-Conversion'!H3:H201,'Zarrah-Conversion'!G3:G201,"Closed Won")+SUMIFS('Home-Conversion'!H4:H202,'Home-Conversion'!G4:G202,"Closed Won")+IF(RepPrefix4="",0,IFERROR(SUMIFS(INDIRECT("'"&RepPrefix4&"- Conversion'!H4:H202"),INDIRECT("'"&RepPrefix4&"- Conversion'!G4:G202"),"Closed Won"),0))+IF(RepPrefix5="",0,IFERROR(SUMIFS(INDIRECT("'"&RepPrefix5&"- Conversion'!H4:H202"),INDIRECT("'"&RepPrefix5&"- Conversion'!G4:G202"),"Closed Won"),0))+IF(RepPrefix6="",0,IFERROR(SUMIFS(INDIRECT("'"&RepPrefix6&"- Conversion'!H4:H202"),INDIRECT("'"&RepPrefix6&"- Conversion'!G4:G202"),"Closed Won"),0)) | K15: =J15*1.0 | L15: 1
B16: TOTAL | C16: =SUM(C10:C15) | D16: =SUM(D10:D15) | E16: =IFERROR(D16/C16,0) | F16: =SUM(F10:F15) | H16: Closed Lost | I16: =COUNTIF('Madine- Conversion'!G4:G202,"Closed Lost")+COUNTIF('Zarrah-Conversion'!G3:G201,"Closed Lost")+COUNTIF('Home-Conversion'!G4:G202,"Closed Lost")+IF(RepPrefix4="",0,IFERROR(COUNTIF(INDIRECT("'"&RepPrefix4&"- Conversion'!G4:G202"),"Closed Lost"),0))+IF(RepPrefix5="",0,IFERROR(COUNTIF(INDIRECT("'"&RepPrefix5&"- Conversion'!G4:G202"),"Closed Lost"),0))+IF(RepPrefix6="",0,IFERROR(COUNTIF(INDIRECT("'"&RepPrefix6&"- Conversion'!G4:G202"),"Closed Lost"),0)) | J16: =SUMIFS('Madine- Conversion'!H4:H202,'Madine- Conversion'!G4:G202,"Closed Lost")+SUMIFS('Zarrah-Conversion'!H3:H201,'Zarrah-Conversion'!G3:G201,"Closed Lost")+SUMIFS('Home-Conversion'!H4:H202,'Home-Conversion'!G4:G202,"Closed Lost")+IF(RepPrefix4="",0,IFERROR(SUMIFS(INDIRECT("'"&RepPrefix4&"- Conversion'!H4:H202"),INDIRECT("'"&RepPrefix4&"- Conversion'!G4:G202"),"Closed Lost"),0))+IF(RepPrefix5="",0,IFERROR(SUMIFS(INDIRECT("'"&RepPrefix5&"- Conversion'!H4:H202"),INDIRECT("'"&RepPrefix5&"- Conversion'!G4:G202"),"Closed Lost"),0))+IF(RepPrefix6="",0,IFERROR(SUMIFS(INDIRECT("'"&RepPrefix6&"- Conversion'!H4:H202"),INDIRECT("'"&RepPrefix6&"- Conversion'!G4:G202"),"Closed Lost"),0)) | K16: 0 | L16: 0
H17: PIPELINE TOTAL | I17: =SUM(I10:I15) | J17: =SUM(J10:J15) | K17: =SUM(K10:K15)
B19: PIPELINE HEALTH · AT-RISK & PAST-DUE DEALS
B20: =SUM('Per-Rep Detail'!M5:M10) | D20: =(SUMPRODUCT(--ISNUMBER('Madine- Conversion'!J4:J202),--('Madine- Conversion'!J4:J202<TODAY()),--('Madine- Conversion'!G4:G202="Opportunity Creation"),'Madine- Conversion'!H4:H202)+SUMPRODUCT(--ISNUMBER('Madine- Conversion'!J4:J202),--('Madine- Conversion'!J4:J202<TODAY()),--('Madine- Conversion'!G4:G202="Scoping"),'Madine- Conversion'!H4:H202)+SUMPRODUCT(--ISNUMBER('Madine- Conversion'!J4:J202),--('Madine- Conversion'!J4:J202<TODAY()),--('Madine- Conversion'!G4:G202="BOM Submission"),'Madine- Conversion'!H4:H202)+SUMPRODUCT(--ISNUMBER('Madine- Conversion'!J4:J202),--('Madine- Conversion'!J4:J202<TODAY()),--('Madine- Conversion'!G4:G202="Resubmission"),'Madine- Conversion'!H4:H202)+SUMPRODUCT(--ISNUMBER('Madine- Conversion'!J4:J202),--('Madine- Conversion'!J4:J202<TODAY()),--('Madine- Conversion'!G4:G202="Negotiation"),'Madine- Conversion'!H4:H202))+(SUMPRODUCT(--ISNUMBER('Zarrah-Conversion'!J3:J201),--('Zarrah-Conversion'!J3:J201<TODAY()),--('Zarrah-Conversion'!G3:G201="Opportunity Creation"),'Zarrah-Conversion'!H3:H201)+SUMPRODUCT(--ISNUMBER('Zarrah-Conversion'!J3:J201),--('Zarrah-Conversion'!J3:J201<TODAY()),--('Zarrah-Conversion'!G3:G201="Scoping"),'Zarrah-Conversion'!H3:H201)+SUMPRODUCT(--ISNUMBER('Zarrah-Conversion'!J3:J201),--('Zarrah-Conversion'!J3:J201<TODAY()),--('Zarrah-Conversion'!G3:G201="BOM Submission"),'Zarrah-Conversion'!H3:H201)+SUMPRODUCT(--ISNUMBER('Zarrah-Conversion'!J3:J201),--('Zarrah-Conversion'!J3:J201<TODAY()),--('Zarrah-Conversion'!G3:G201="Resubmission"),'Zarrah-Conversion'!H3:H201)+SUMPRODUCT(--ISNUMBER('Zarrah-Conversion'!J3:J201),--('Zarrah-Conversion'!J3:J201<TODAY()),--('Zarrah-Conversion'!G3:G201="Negotiation"),'Zarrah-Conversion'!H3:H201))+(SUMPRODUCT(--ISNUMBER('Home-Conversion'!J4:J202),--('Home-Conversion'!J4:J202<TODAY()),--('Home-Conversion'!G4:G202="Opportunity Creation"),'Home-Conversion'!H4:H202)+SUMPRODUCT(--ISNUMBER('Home-Conversion'!J4:J202),--('Home-Conversion'!J4:J202<TODAY()),--('Home-Conversion'!G4:G202="Scoping"),'Home-Conversion'!H4:H202)+SUMPRODUCT(--ISNUMBER('Home-Conversion'!J4:J202),--('Home-Conversion'!J4:J202<TODAY()),--('Home-Conversion'!G4:G202="BOM Submission"),'Home-Conversion'!H4:H202)+SUMPRODUCT(--ISNUMBER('Home-Conversion'!J4:J202),--('Home-Conversion'!J4:J202<TODAY()),--('Home-Conversion'!G4:G202="Resubmission"),'Home-Conversion'!H4:H202)+SUMPRODUCT(--ISNUMBER('Home-Conversion'!J4:J202),--('Home-Conversion'!J4:J202<TODAY()),--('Home-Conversion'!G4:G202="Negotiation"),'Home-Conversion'!H4:H202))+IF(RepPrefix4="",0,IFERROR((SUMPRODUCT(--ISNUMBER(INDIRECT("'"&RepPrefix4&"- Conversion'!J4:J202")),--(INDIRECT("'"&RepPrefix4&"- Conversion'!J4:J202")<TODAY()),--(INDIRECT("'"&RepPrefix4&"- Conversion'!G4:G202")="Opportunity Creation"),INDIRECT("'"&RepPrefix4&"- Conversion'!H4:H202"))+SUMPRODUCT(--ISNUMBER(INDIRECT("'"&RepPrefix4&"- Conversion'!J4:J202")),--(INDIRECT("'"&RepPrefix4&"- Conversion'!J4:J202")<TODAY()),--(INDIRECT("'"&RepPrefix4&"- Conversion'!G4:G202")="Scoping"),INDIRECT("'"&RepPrefix4&"- Conversion'!H4:H202"))+SUMPRODUCT(--ISNUMBER(INDIRECT("'"&RepPrefix4&"- Conversion'!J4:J202")),--(INDIRECT("'"&RepPrefix4&"- Conversion'!J4:J202")<TODAY()),--(INDIRECT("'"&RepPrefix4&"- Conversion'!G4:G202")="BOM Submission"),INDIRECT("'"&RepPrefix4&"- Conversion'!H4:H202"))+SUMPRODUCT(--ISNUMBER(INDIRECT("'"&RepPrefix4&"- Conversion'!J4:J202")),--(INDIRECT("'"&RepPrefix4&"- Conversion'!J4:J202")<TODAY()),--(INDIRECT("'"&RepPrefix4&"- Conversion'!G4:G202")="Resubmission"),INDIRECT("'"&RepPrefix4&"- Conversion'!H4:H202"))+SUMPRODUCT(--ISNUMBER(INDIRECT("'"&RepPrefix4&"- Conversion'!J4:J202")),--(INDIRECT("'"&RepPrefix4&"- Conversion'!J4:J202")<TODAY()),--(INDIRECT("'"&RepPrefix4&"- Conversion'!G4:G202")="Negotiation"),INDIRECT("'"&RepPrefix4&"- Conversion'!H4:H202"))),0))+IF(RepPrefix5="",0,IFERROR((SUMPRODUCT(--ISNUMBER(INDIRECT("'"&RepPrefix5&"- Conversion'!J4:J202")),--(INDIRECT("'"&RepPrefix5&"- Conversion'!J4:J202")<TODAY()),--(INDIRECT("'"&RepPrefix5&"- Conversion'!G4:G202")="Opportunity Creation"),INDIRECT("'"&RepPrefix5&"- Conversion'!H4:H202"))+SUMPRODUCT(--ISNUMBER(INDIRECT("'"&RepPrefix5&"- Conversion'!J4:J202")),--(INDIRECT("'"&RepPrefix5&"- Conversion'!J4:J202")<TODAY()),--(INDIRECT("'"&RepPrefix5&"- Conversion'!G4:G202")="Scoping"),INDIRECT("'"&RepPrefix5&"- Conversion'!H4:H202"))+SUMPRODUCT(--ISNUMBER(INDIRECT("'"&RepPrefix5&"- Conversion'!J4:J202")),--(INDIRECT("'"&RepPrefix5&"- Conversion'!J4:J202")<TODAY()),--(INDIRECT("'"&RepPrefix5&"- Conversion'!G4:G202")="BOM Submission"),INDIRECT("'"&RepPrefix5&"- Conversion'!H4:H202"))+SUMPRODUCT(--ISNUMBER(INDIRECT("'"&RepPrefix5&"- Conversion'!J4:J202")),--(INDIRECT("'"&RepPrefix5&"- Conversion'!J4:J202")<TODAY()),--(INDIRECT("'"&RepPrefix5&"- Conversion'!G4:G202")="Resubmission"),INDIRECT("'"&RepPrefix5&"- Conversion'!H4:H202"))+SUMPRODUCT(--ISNUMBER(INDIRECT("'"&RepPrefix5&"- Conversion'!J4:J202")),--(INDIRECT("'"&RepPrefix5&"- Conversion'!J4:J202")<TODAY()),--(INDIRECT("'"&RepPrefix5&"- Conversion'!G4:G202")="Negotiation"),INDIRECT("'"&RepPrefix5&"- Conversion'!H4:H202"))),0))+IF(RepPrefix6="",0,IFERROR((SUMPRODUCT(--ISNUMBER(INDIRECT("'"&RepPrefix6&"- Conversion'!J4:J202")),--(INDIRECT("'"&RepPrefix6&"- Conversion'!J4:J202")<TODAY()),--(INDIRECT("'"&RepPrefix6&"- Conversion'!G4:G202")="Opportunity Creation"),INDIRECT("'"&RepPrefix6&"- Conversion'!H4:H202"))+SUMPRODUCT(--ISNUMBER(INDIRECT("'"&RepPrefix6&"- Conversion'!J4:J202")),--(INDIRECT("'"&RepPrefix6&"- Conversion'!J4:J202")<TODAY()),--(INDIRECT("'"&RepPrefix6&"- Conversion'!G4:G202")="Scoping"),INDIRECT("'"&RepPrefix6&"- Conversion'!H4:H202"))+SUMPRODUCT(--ISNUMBER(INDIRECT("'"&RepPrefix6&"- Conversion'!J4:J202")),--(INDIRECT("'"&RepPrefix6&"- Conversion'!J4:J202")<TODAY()),--(INDIRECT("'"&RepPrefix6&"- Conversion'!G4:G202")="BOM Submission"),INDIRECT("'"&RepPrefix6&"- Conversion'!H4:H202"))+SUMPRODUCT(--ISNUMBER(INDIRECT("'"&RepPrefix6&"- Conversion'!J4:J202")),--(INDIRECT("'"&RepPrefix6&"- Conversion'!J4:J202")<TODAY()),--(INDIRECT("'"&RepPrefix6&"- Conversion'!G4:G202")="Resubmission"),INDIRECT("'"&RepPrefix6&"- Conversion'!H4:H202"))+SUMPRODUCT(--ISNUMBER(INDIRECT("'"&RepPrefix6&"- Conversion'!J4:J202")),--(INDIRECT("'"&RepPrefix6&"- Conversion'!J4:J202")<TODAY()),--(INDIRECT("'"&RepPrefix6&"- Conversion'!G4:G202")="Negotiation"),INDIRECT("'"&RepPrefix6&"- Conversion'!H4:H202"))),0)) | F20: =SUM('Per-Rep Detail'!C5:C10) | H20: =IFERROR(('Per-Rep Detail'!D11+'Per-Rep Detail'!E11+'Per-Rep Detail'!F11)/'Per-Rep Detail'!C11,0) | J20: =IFERROR((SUMIFS('Madine- Conversion'!H4:H202,'Madine- Conversion'!G4:G202,"Closed Lost")+SUMIFS('Zarrah-Conversion'!H3:H201,'Zarrah-Conversion'!G3:G201,"Closed Lost")+SUMIFS('Home-Conversion'!H4:H202,'Home-Conversion'!G4:G202,"Closed Lost")+IF(RepPrefix4="",0,IFERROR(SUMIFS(INDIRECT("'"&RepPrefix4&"- Conversion'!H4:H202"),INDIRECT("'"&RepPrefix4&"- Conversion'!G4:G202"),"Closed Lost"),0))+IF(RepPrefix5="",0,IFERROR(SUMIFS(INDIRECT("'"&RepPrefix5&"- Conversion'!H4:H202"),INDIRECT("'"&RepPrefix5&"- Conversion'!G4:G202"),"Closed Lost"),0))+IF(RepPrefix6="",0,IFERROR(SUMIFS(INDIRECT("'"&RepPrefix6&"- Conversion'!H4:H202"),INDIRECT("'"&RepPrefix6&"- Conversion'!G4:G202"),"Closed Lost"),0)))/(((SUMIFS('Madine- Conversion'!H4:H202,'Madine- Conversion'!G4:G202,"Closed Won")+SUMIFS('Zarrah-Conversion'!H3:H201,'Zarrah-Conversion'!G3:G201,"Closed Won")+SUMIFS('Home-Conversion'!H4:H202,'Home-Conversion'!G4:G202,"Closed Won")+IF(RepPrefix4="",0,IFERROR(SUMIFS(INDIRECT("'"&RepPrefix4&"- Conversion'!H4:H202"),INDIRECT("'"&RepPrefix4&"- Conversion'!G4:G202"),"Closed Won"),0))+IF(RepPrefix5="",0,IFERROR(SUMIFS(INDIRECT("'"&RepPrefix5&"- Conversion'!H4:H202"),INDIRECT("'"&RepPrefix5&"- Conversion'!G4:G202"),"Closed Won"),0))+IF(RepPrefix6="",0,IFERROR(SUMIFS(INDIRECT("'"&RepPrefix6&"- Conversion'!H4:H202"),INDIRECT("'"&RepPrefix6&"- Conversion'!G4:G202"),"Closed Won"),0))))+(SUMIFS('Madine- Conversion'!H4:H202,'Madine- Conversion'!G4:G202,"Closed Lost")+SUMIFS('Zarrah-Conversion'!H3:H201,'Zarrah-Conversion'!G3:G201,"Closed Lost")+SUMIFS('Home-Conversion'!H4:H202,'Home-Conversion'!G4:G202,"Closed Lost")+IF(RepPrefix4="",0,IFERROR(SUMIFS(INDIRECT("'"&RepPrefix4&"- Conversion'!H4:H202"),INDIRECT("'"&RepPrefix4&"- Conversion'!G4:G202"),"Closed Lost"),0))+IF(RepPrefix5="",0,IFERROR(SUMIFS(INDIRECT("'"&RepPrefix5&"- Conversion'!H4:H202"),INDIRECT("'"&RepPrefix5&"- Conversion'!G4:G202"),"Closed Lost"),0))+IF(RepPrefix6="",0,IFERROR(SUMIFS(INDIRECT("'"&RepPrefix6&"- Conversion'!H4:H202"),INDIRECT("'"&RepPrefix6&"- Conversion'!G4:G202"),"Closed Lost"),0)))),0) | L20: =IFERROR(F16/Quota,0)
B21: PAST-DUE DEALS | D21: PAST-DUE TCV | F21: COVERAGE LEADS | H21: COV→CONV % | J21: LOST RATE (₱) | L21: PIPE COVERAGE
B23: TOP DEALS — DRILL TO 'Pipeline Health' SHEET FOR FULL LIST
B24: ACCOUNT | E24: REP | F24: STAGE | H24: TCV | J24: GP | L24: CLOSING | N24: FLAG
B25: ='Pipeline Health'!B5 | E25: ='Pipeline Health'!C5 | F25: ='Pipeline Health'!D5 | H25: ='Pipeline Health'!E5 | J25: ='Pipeline Health'!F5 | L25: ='Pipeline Health'!G5 | N25: ='Pipeline Health'!H5
B26: ='Pipeline Health'!B6 | E26: ='Pipeline Health'!C6 | F26: ='Pipeline Health'!D6 | H26: ='Pipeline Health'!E6 | J26: ='Pipeline Health'!F6 | L26: ='Pipeline Health'!G6 | N26: ='Pipeline Health'!H6
B27: ='Pipeline Health'!B7 | E27: ='Pipeline Health'!C7 | F27: ='Pipeline Health'!D7 | H27: ='Pipeline Health'!E7 | J27: ='Pipeline Health'!F7 | L27: ='Pipeline Health'!G7 | N27: ='Pipeline Health'!H7
B28: ='Pipeline Health'!B8 | E28: ='Pipeline Health'!C8 | F28: ='Pipeline Health'!D8 | H28: ='Pipeline Health'!E8 | J28: ='Pipeline Health'!F8 | L28: ='Pipeline Health'!G8 | N28: ='Pipeline Health'!H8
B29: ='Pipeline Health'!B9 | E29: ='Pipeline Health'!C9 | F29: ='Pipeline Health'!D9 | H29: ='Pipeline Health'!E9 | J29: ='Pipeline Health'!F9 | L29: ='Pipeline Health'!G9 | N29: ='Pipeline Health'!H9
B30: ='Pipeline Health'!B10 | E30: ='Pipeline Health'!C10 | F30: ='Pipeline Health'!D10 | H30: ='Pipeline Health'!E10 | J30: ='Pipeline Health'!F10 | L30: ='Pipeline Health'!G10 | N30: ='Pipeline Health'!H10
B32: Live formulas · Edit source sheets to refresh · Inputs sheet drives quota/thresholds

Sheet Per-Rep Detail
B2: PER-REP DETAIL · LEADERBOARD
B4: REP | C4: Coverage Leads | D4: Active Opps | E4: Closed Won | F4: Closed Lost | G4: Win Rate | H4: TCV (Pipe+Won) | I4: GP (Pipe+Won) | J4: GP % | K4: Weighted Pipe | L4: Avg Deal Size | M4: Past-Due Deals
B5: =RepName1 | C5: =COUNTIFS('Madine- Coverage'!C4:C202,"<>") | D5: =(COUNTIFS('Madine- Conversion'!G4:G202,"<>Closed Lost",'Madine- Conversion'!G4:G202,"<>Closed Won",'Madine- Conversion'!G4:G202,"<>")) | E5: =COUNTIF('Madine- Conversion'!G4:G202,"Closed Won") | F5: =COUNTIF('Madine- Conversion'!G4:G202,"Closed Lost") | G5: =IFERROR(COUNTIF('Madine- Conversion'!G4:G202,"Closed Won")/(COUNTIF('Madine- Conversion'!G4:G202,"Closed Won")+COUNTIF('Madine- Conversion'!G4:G202,"Closed Lost")),0) | H5: =(SUMIFS('Madine- Conversion'!H4:H202,'Madine- Conversion'!G4:G202,"<>Closed Lost",'Madine- Conversion'!G4:G202,"<>")) | I5: =(SUMIFS('Madine- Conversion'!I4:I202,'Madine- Conversion'!G4:G202,"<>Closed Lost",'Madine- Conversion'!G4:G202,"<>")) | J5: =IFERROR(I5/H5,0) | K5: =((SUMIFS('Madine- Conversion'!H4:H202,'Madine- Conversion'!G4:G202,"Opportunity Creation")*0.1+SUMIFS('Madine- Conversion'!H4:H202,'Madine- Conversion'!G4:G202,"Scoping")*0.3+SUMIFS('Madine- Conversion'!H4:H202,'Madine- Conversion'!G4:G202,"BOM Submission")*0.5+SUMIFS('Madine- Conversion'!H4:H202,'Madine- Conversion'!G4:G202,"Resubmission")*0.7+SUMIFS('Madine- Conversion'!H4:H202,'Madine- Conversion'!G4:G202,"Negotiation")*0.9)) | L5: =IFERROR(H5/(D5+E5),0) | M5: =((SUMPRODUCT(--ISNUMBER('Madine- Conversion'!J4:J202),--('Madine- Conversion'!J4:J202<TODAY()),--('Madine- Conversion'!G4:G202="Opportunity Creation"))+SUMPRODUCT(--ISNUMBER('Madine- Conversion'!J4:J202),--('Madine- Conversion'!J4:J202<TODAY()),--('Madine- Conversion'!G4:G202="Scoping"))+SUMPRODUCT(--ISNUMBER('Madine- Conversion'!J4:J202),--('Madine- Conversion'!J4:J202<TODAY()),--('Madine- Conversion'!G4:G202="BOM Submission"))+SUMPRODUCT(--ISNUMBER('Madine- Conversion'!J4:J202),--('Madine- Conversion'!J4:J202<TODAY()),--('Madine- Conversion'!G4:G202="Resubmission"))+SUMPRODUCT(--ISNUMBER('Madine- Conversion'!J4:J202),--('Madine- Conversion'!J4:J202<TODAY()),--('Madine- Conversion'!G4:G202="Negotiation"))))
B6: =RepName2 | C6: =COUNTIFS('Zarrah- Coverage'!C4:C202,"<>") | D6: =(COUNTIFS('Zarrah-Conversion'!G3:G201,"<>Closed Lost",'Zarrah-Conversion'!G3:G201,"<>Closed Won",'Zarrah-Conversion'!G3:G201,"<>")) | E6: =COUNTIF('Zarrah-Conversion'!G3:G201,"Closed Won") | F6: =COUNTIF('Zarrah-Conversion'!G3:G201,"Closed Lost") | G6: =IFERROR(COUNTIF('Zarrah-Conversion'!G3:G201,"Closed Won")/(COUNTIF('Zarrah-Conversion'!G3:G201,"Closed Won")+COUNTIF('Zarrah-Conversion'!G3:G201,"Closed Lost")),0) | H6: =(SUMIFS('Zarrah-Conversion'!H3:H201,'Zarrah-Conversion'!G3:G201,"<>Closed Lost",'Zarrah-Conversion'!G3:G201,"<>")) | I6: =(SUMIFS('Zarrah-Conversion'!I3:I201,'Zarrah-Conversion'!G3:G201,"<>Closed Lost",'Zarrah-Conversion'!G3:G201,"<>")) | J6: =IFERROR(I6/H6,0) | K6: =((SUMIFS('Zarrah-Conversion'!H3:H201,'Zarrah-Conversion'!G3:G201,"Opportunity Creation")*0.1+SUMIFS('Zarrah-Conversion'!H3:H201,'Zarrah-Conversion'!G3:G201,"Scoping")*0.3+SUMIFS('Zarrah-Conversion'!H3:H201,'Zarrah-Conversion'!G3:G201,"BOM Submission")*0.5+SUMIFS('Zarrah-Conversion'!H3:H201,'Zarrah-Conversion'!G3:G201,"Resubmission")*0.7+SUMIFS('Zarrah-Conversion'!H3:H201,'Zarrah-Conversion'!G3:G201,"Negotiation")*0.9)) | L6: =IFERROR(H6/(D6+E6),0) | M6: =((SUMPRODUCT(--ISNUMBER('Zarrah-Conversion'!J3:J201),--('Zarrah-Conversion'!J3:J201<TODAY()),--('Zarrah-Conversion'!G3:G201="Opportunity Creation"))+SUMPRODUCT(--ISNUMBER('Zarrah-Conversion'!J3:J201),--('Zarrah-Conversion'!J3:J201<TODAY()),--('Zarrah-Conversion'!G3:G201="Scoping"))+SUMPRODUCT(--ISNUMBER('Zarrah-Conversion'!J3:J201),--('Zarrah-Conversion'!J3:J201<TODAY()),--('Zarrah-Conversion'!G3:G201="BOM Submission"))+SUMPRODUCT(--ISNUMBER('Zarrah-Conversion'!J3:J201),--('Zarrah-Conversion'!J3:J201<TODAY()),--('Zarrah-Conversion'!G3:G201="Resubmission"))+SUMPRODUCT(--ISNUMBER('Zarrah-Conversion'!J3:J201),--('Zarrah-Conversion'!J3:J201<TODAY()),--('Zarrah-Conversion'!G3:G201="Negotiation"))))
B7: =RepName3 | C7: =COUNTIFS('Home-Coverage'!C4:C202,"<>") | D7: =(COUNTIFS('Home-Conversion'!G4:G202,"<>Closed Lost",'Home-Conversion'!G4:G202,"<>Closed Won",'Home-Conversion'!G4:G202,"<>")) | E7: =COUNTIF('Home-Conversion'!G4:G202,"Closed Won") | F7: =COUNTIF('Home-Conversion'!G4:G202,"Closed Lost") | G7: =IFERROR(COUNTIF('Home-Conversion'!G4:G202,"Closed Won")/(COUNTIF('Home-Conversion'!G4:G202,"Closed Won")+COUNTIF('Home-Conversion'!G4:G202,"Closed Lost")),0) | H7: =(SUMIFS('Home-Conversion'!H4:H202,'Home-Conversion'!G4:G202,"<>Closed Lost",'Home-Conversion'!G4:G202,"<>")) | I7: =(SUMIFS('Home-Conversion'!I4:I202,'Home-Conversion'!G4:G202,"<>Closed Lost",'Home-Conversion'!G4:G202,"<>")) | J7: =IFERROR(I7/H7,0) | K7: =((SUMIFS('Home-Conversion'!H4:H202,'Home-Conversion'!G4:G202,"Opportunity Creation")*0.1+SUMIFS('Home-Conversion'!H4:H202,'Home-Conversion'!G4:G202,"Scoping")*0.3+SUMIFS('Home-Conversion'!H4:H202,'Home-Conversion'!G4:G202,"BOM Submission")*0.5+SUMIFS('Home-Conversion'!H4:H202,'Home-Conversion'!G4:G202,"Resubmission")*0.7+SUMIFS('Home-Conversion'!H4:H202,'Home-Conversion'!G4:G202,"Negotiation")*0.9)) | L7: =IFERROR(H7/(D7+E7),0) | M7: =((SUMPRODUCT(--ISNUMBER('Home-Conversion'!J4:J202),--('Home-Conversion'!J4:J202<TODAY()),--('Home-Conversion'!G4:G202="Opportunity Creation"))+SUMPRODUCT(--ISNUMBER('Home-Conversion'!J4:J202),--('Home-Conversion'!J4:J202<TODAY()),--('Home-Conversion'!G4:G202="Scoping"))+SUMPRODUCT(--ISNUMBER('Home-Conversion'!J4:J202),--('Home-Conversion'!J4:J202<TODAY()),--('Home-Conversion'!G4:G202="BOM Submission"))+SUMPRODUCT(--ISNUMBER('Home-Conversion'!J4:J202),--('Home-Conversion'!J4:J202<TODAY()),--('Home-Conversion'!G4:G202="Resubmission"))+SUMPRODUCT(--ISNUMBER('Home-Conversion'!J4:J202),--('Home-Conversion'!J4:J202<TODAY()),--('Home-Conversion'!G4:G202="Negotiation"))))
B8: =IF(RepPrefix4="","",RepName4) | C8: =IF(RepPrefix4="","",IF(RepPrefix4="",0,IFERROR(COUNTIFS(INDIRECT("'"&RepPrefix4&"- Coverage'!C4:C202"),"<>"),0))) | D8: =IF(RepPrefix4="","",(IF(RepPrefix4="",0,IFERROR(COUNTIFS(INDIRECT("'"&RepPrefix4&"- Conversion'!G4:G202"),"<>Closed Lost",INDIRECT("'"&RepPrefix4&"- Conversion'!G4:G202"),"<>Closed Won",INDIRECT("'"&RepPrefix4&"- Conversion'!G4:G202"),"<>"),0)))) | E8: =IF(RepPrefix4="","",IF(RepPrefix4="",0,IFERROR(COUNTIF(INDIRECT("'"&RepPrefix4&"- Conversion'!G4:G202"),"Closed Won"),0))) | F8: =IF(RepPrefix4="","",IF(RepPrefix4="",0,IFERROR(COUNTIF(INDIRECT("'"&RepPrefix4&"- Conversion'!G4:G202"),"Closed Lost"),0))) | G8: =IF(RepPrefix4="","",IFERROR(IF(RepPrefix4="",0,IFERROR(COUNTIF(INDIRECT("'"&RepPrefix4&"- Conversion'!G4:G202"),"Closed Won"),0))/(IF(RepPrefix4="",0,IFERROR(COUNTIF(INDIRECT("'"&RepPrefix4&"- Conversion'!G4:G202"),"Closed Won"),0))+IF(RepPrefix4="",0,IFERROR(COUNTIF(INDIRECT("'"&RepPrefix4&"- Conversion'!G4:G202"),"Closed Lost"),0))),0)) | H8: =IF(RepPrefix4="","",(IF(RepPrefix4="",0,IFERROR(SUMIFS(INDIRECT("'"&RepPrefix4&"- Conversion'!H4:H202"),INDIRECT("'"&RepPrefix4&"- Conversion'!G4:G202"),"<>Closed Lost",INDIRECT("'"&RepPrefix4&"- Conversion'!G4:G202"),"<>"),0)))) | I8: =IF(RepPrefix4="","",(IF(RepPrefix4="",0,IFERROR(SUMIFS(INDIRECT("'"&RepPrefix4&"- Conversion'!I4:I202"),INDIRECT("'"&RepPrefix4&"- Conversion'!G4:G202"),"<>Closed Lost",INDIRECT("'"&RepPrefix4&"- Conversion'!G4:G202"),"<>"),0)))) | J8: =IFERROR(I8/H8,0) | K8: =IF(RepPrefix4="","",((IF(RepPrefix4="",0,IFERROR(SUMIFS(INDIRECT("'"&RepPrefix4&"- Conversion'!H4:H202"),INDIRECT("'"&RepPrefix4&"- Conversion'!G4:G202"),"Opportunity Creation"),0))*0.1+IF(RepPrefix4="",0,IFERROR(SUMIFS(INDIRECT("'"&RepPrefix4&"- Conversion'!H4:H202"),INDIRECT("'"&RepPrefix4&"- Conversion'!G4:G202"),"Scoping"),0))*0.3+IF(RepPrefix4="",0,IFERROR(SUMIFS(INDIRECT("'"&RepPrefix4&"- Conversion'!H4:H202"),INDIRECT("'"&RepPrefix4&"- Conversion'!G4:G202"),"BOM Submission"),0))*0.5+IF(RepPrefix4="",0,IFERROR(SUMIFS(INDIRECT("'"&RepPrefix4&"- Conversion'!H4:H202"),INDIRECT("'"&RepPrefix4&"- Conversion'!G4:G202"),"Resubmission"),0))*0.7+IF(RepPrefix4="",0,IFERROR(SUMIFS(INDIRECT("'"&RepPrefix4&"- Conversion'!H4:H202"),INDIRECT("'"&RepPrefix4&"- Conversion'!G4:G202"),"Negotiation"),0))*0.9))) | L8: =IFERROR(H8/(D8+E8),0) | M8: =IF(RepPrefix4="","",(IF(RepPrefix4="",0,IFERROR((SUMPRODUCT(--ISNUMBER(INDIRECT("'"&RepPrefix4&"- Conversion'!J4:J202")),--(INDIRECT("'"&RepPrefix4&"- Conversion'!J4:J202")<TODAY()),--(INDIRECT("'"&RepPrefix4&"- Conversion'!G4:G202")="Opportunity Creation"))+SUMPRODUCT(--ISNUMBER(INDIRECT("'"&RepPrefix4&"- Conversion'!J4:J202")),--(INDIRECT("'"&RepPrefix4&"- Conversion'!J4:J202")<TODAY()),--(INDIRECT("'"&RepPrefix4&"- Conversion'!G4:G202")="Scoping"))+SUMPRODUCT(--ISNUMBER(INDIRECT("'"&RepPrefix4&"- Conversion'!J4:J202")),--(INDIRECT("'"&RepPrefix4&"- Conversion'!J4:J202")<TODAY()),--(INDIRECT("'"&RepPrefix4&"- Conversion'!G4:G202")="BOM Submission"))+SUMPRODUCT(--ISNUMBER(INDIRECT("'"&RepPrefix4&"- Conversion'!J4:J202")),--(INDIRECT("'"&RepPrefix4&"- Conversion'!J4:J202")<TODAY()),--(INDIRECT("'"&RepPrefix4&"- Conversion'!G4:G202")="Resubmission"))+SUMPRODUCT(--ISNUMBER(INDIRECT("'"&RepPrefix4&"- Conversion'!J4:J202")),--(INDIRECT("'"&RepPrefix4&"- Conversion'!J4:J202")<TODAY()),--(INDIRECT("'"&RepPrefix4&"- Conversion'!G4:G202")="Negotiation"))),0))))
B9: =IF(RepPrefix5="","",RepName5) | C9: =IF(RepPrefix5="","",IF(RepPrefix5="",0,IFERROR(COUNTIFS(INDIRECT("'"&RepPrefix5&"- Coverage'!C4:C202"),"<>"),0))) | D9: =IF(RepPrefix5="","",(IF(RepPrefix5="",0,IFERROR(COUNTIFS(INDIRECT("'"&RepPrefix5&"- Conversion'!G4:G202"),"<>Closed Lost",INDIRECT("'"&RepPrefix5&"- Conversion'!G4:G202"),"<>Closed Won",INDIRECT("'"&RepPrefix5&"- Conversion'!G4:G202"),"<>"),0)))) | E9: =IF(RepPrefix5="","",IF(RepPrefix5="",0,IFERROR(COUNTIF(INDIRECT("'"&RepPrefix5&"- Conversion'!G4:G202"),"Closed Won"),0))) | F9: =IF(RepPrefix5="","",IF(RepPrefix5="",0,IFERROR(COUNTIF(INDIRECT("'"&RepPrefix5&"- Conversion'!G4:G202"),"Closed Lost"),0))) | G9: =IF(RepPrefix5="","",IFERROR(IF(RepPrefix5="",0,IFERROR(COUNTIF(INDIRECT("'"&RepPrefix5&"- Conversion'!G4:G202"),"Closed Won"),0))/(IF(RepPrefix5="",0,IFERROR(COUNTIF(INDIRECT("'"&RepPrefix5&"- Conversion'!G4:G202"),"Closed Won"),0))+IF(RepPrefix5="",0,IFERROR(COUNTIF(INDIRECT("'"&RepPrefix5&"- Conversion'!G4:G202"),"Closed Lost"),0))),0)) | H9: =IF(RepPrefix5="","",(IF(RepPrefix5="",0,IFERROR(SUMIFS(INDIRECT("'"&RepPrefix5&"- Conversion'!H4:H202"),INDIRECT("'"&RepPrefix5&"- Conversion'!G4:G202"),"<>Closed Lost",INDIRECT("'"&RepPrefix5&"- Conversion'!G4:G202"),"<>"),0)))) | I9: =IF(RepPrefix5="","",(IF(RepPrefix5="",0,IFERROR(SUMIFS(INDIRECT("'"&RepPrefix5&"- Conversion'!I4:I202"),INDIRECT("'"&RepPrefix5&"- Conversion'!G4:G202"),"<>Closed Lost",INDIRECT("'"&RepPrefix5&"- Conversion'!G4:G202"),"<>"),0)))) | J9: =IFERROR(I9/H9,0) | K9: =IF(RepPrefix5="","",((IF(RepPrefix5="",0,IFERROR(SUMIFS(INDIRECT("'"&RepPrefix5&"- Conversion'!H4:H202"),INDIRECT("'"&RepPrefix5&"- Conversion'!G4:G202"),"Opportunity Creation"),0))*0.1+IF(RepPrefix5="",0,IFERROR(SUMIFS(INDIRECT("'"&RepPrefix5&"- Conversion'!H4:H202"),INDIRECT("'"&RepPrefix5&"- Conversion'!G4:G202"),"Scoping"),0))*0.3+IF(RepPrefix5="",0,IFERROR(SUMIFS(INDIRECT("'"&RepPrefix5&"- Conversion'!H4:H202"),INDIRECT("'"&RepPrefix5&"- Conversion'!G4:G202"),"BOM Submission"),0))*0.5+IF(RepPrefix5="",0,IFERROR(SUMIFS(INDIRECT("'"&RepPrefix5&"- Conversion'!H4:H202"),INDIRECT("'"&RepPrefix5&"- Conversion'!G4:G202"),"Resubmission"),0))*0.7+IF(RepPrefix5="",0,IFERROR(SUMIFS(INDIRECT("'"&RepPrefix5&"- Conversion'!H4:H202"),INDIRECT("'"&RepPrefix5&"- Conversion'!G4:G202"),"Negotiation"),0))*0.9))) | L9: =IFERROR(H9/(D9+E9),0) | M9: =IF(RepPrefix5="","",(IF(RepPrefix5="",0,IFERROR((SUMPRODUCT(--ISNUMBER(INDIRECT("'"&RepPrefix5&"- Conversion'!J4:J202")),--(INDIRECT("'"&RepPrefix5&"- Conversion'!J4:J202")<TODAY()),--(INDIRECT("'"&RepPrefix5&"- Conversion'!G4:G202")="Opportunity Creation"))+SUMPRODUCT(--ISNUMBER(INDIRECT("'"&RepPrefix5&"- Conversion'!J4:J202")),--(INDIRECT("'"&RepPrefix5&"- Conversion'!J4:J202")<TODAY()),--(INDIRECT("'"&RepPrefix5&"- Conversion'!G4:G202")="Scoping"))+SUMPRODUCT(--ISNUMBER(INDIRECT("'"&RepPrefix5&"- Conversion'!J4:J202")),--(INDIRECT("'"&RepPrefix5&"- Conversion'!J4:J202")<TODAY()),--(INDIRECT("'"&RepPrefix5&"- Conversion'!G4:G202")="BOM Submission"))+SUMPRODUCT(--ISNUMBER(INDIRECT("'"&RepPrefix5&"- Conversion'!J4:J202")),--(INDIRECT("'"&RepPrefix5&"- Conversion'!J4:J202")<TODAY()),--(INDIRECT("'"&RepPrefix5&"- Conversion'!G4:G202")="Resubmission"))+SUMPRODUCT(--ISNUMBER(INDIRECT("'"&RepPrefix5&"- Conversion'!J4:J202")),--(INDIRECT("'"&RepPrefix5&"- Conversion'!J4:J202")<TODAY()),--(INDIRECT("'"&RepPrefix5&"- Conversion'!G4:G202")="Negotiation"))),0))))
B10: =IF(RepPrefix6="","",RepName6) | C10: =IF(RepPrefix6="","",IF(RepPrefix6="",0,IFERROR(COUNTIFS(INDIRECT("'"&RepPrefix6&"- Coverage'!C4:C202"),"<>"),0))) | D10: =IF(RepPrefix6="","",(IF(RepPrefix6="",0,IFERROR(COUNTIFS(INDIRECT("'"&RepPrefix6&"- Conversion'!G4:G202"),"<>Closed Lost",INDIRECT("'"&RepPrefix6&"- Conversion'!G4:G202"),"<>Closed Won",INDIRECT("'"&RepPrefix6&"- Conversion'!G4:G202"),"<>"),0)))) | E10: =IF(RepPrefix6="","",IF(RepPrefix6="",0,IFERROR(COUNTIF(INDIRECT("'"&RepPrefix6&"- Conversion'!G4:G202"),"Closed Won"),0))) | F10: =IF(RepPrefix6="","",IF(RepPrefix6="",0,IFERROR(COUNTIF(INDIRECT("'"&RepPrefix6&"- Conversion'!G4:G202"),"Closed Lost"),0))) | G10: =IF(RepPrefix6="","",IFERROR(IF(RepPrefix6="",0,IFERROR(COUNTIF(INDIRECT("'"&RepPrefix6&"- Conversion'!G4:G202"),"Closed Won"),0))/(IF(RepPrefix6="",0,IFERROR(COUNTIF(INDIRECT("'"&RepPrefix6&"- Conversion'!G4:G202"),"Closed Won"),0))+IF(RepPrefix6="",0,IFERROR(COUNTIF(INDIRECT("'"&RepPrefix6&"- Conversion'!G4:G202"),"Closed Lost"),0))),0)) | H10: =IF(RepPrefix6="","",(IF(RepPrefix6="",0,IFERROR(SUMIFS(INDIRECT("'"&RepPrefix6&"- Conversion'!H4:H202"),INDIRECT("'"&RepPrefix6&"- Conversion'!G4:G202"),"<>Closed Lost",INDIRECT("'"&RepPrefix6&"- Conversion'!G4:G202"),"<>"),0)))) | I10: =IF(RepPrefix6="","",(IF(RepPrefix6="",0,IFERROR(SUMIFS(INDIRECT("'"&RepPrefix6&"- Conversion'!I4:I202"),INDIRECT("'"&RepPrefix6&"- Conversion'!G4:G202"),"<>Closed Lost",INDIRECT("'"&RepPrefix6&"- Conversion'!G4:G202"),"<>"),0)))) | J10: =IFERROR(I10/H10,0) | K10: =IF(RepPrefix6="","",((IF(RepPrefix6="",0,IFERROR(SUMIFS(INDIRECT("'"&RepPrefix6&"- Conversion'!H4:H202"),INDIRECT("'"&RepPrefix6&"- Conversion'!G4:G202"),"Opportunity Creation"),0))*0.1+IF(RepPrefix6="",0,IFERROR(SUMIFS(INDIRECT("'"&RepPrefix6&"- Conversion'!H4:H202"),INDIRECT("'"&RepPrefix6&"- Conversion'!G4:G202"),"Scoping"),0))*0.3+IF(RepPrefix6="",0,IFERROR(SUMIFS(INDIRECT("'"&RepPrefix6&"- Conversion'!H4:H202"),INDIRECT("'"&RepPrefix6&"- Conversion'!G4:G202"),"BOM Submission"),0))*0.5+IF(RepPrefix6="",0,IFERROR(SUMIFS(INDIRECT("'"&RepPrefix6&"- Conversion'!H4:H202"),INDIRECT("'"&RepPrefix6&"- Conversion'!G4:G202"),"Resubmission"),0))*0.7+IF(RepPrefix6="",0,IFERROR(SUMIFS(INDIRECT("'"&RepPrefix6&"- Conversion'!H4:H202"),INDIRECT("'"&RepPrefix6&"- Conversion'!G4:G202"),"Negotiation"),0))*0.9))) | L10: =IFERROR(H10/(D10+E10),0) | M10: =IF(RepPrefix6="","",(IF(RepPrefix6="",0,IFERROR((SUMPRODUCT(--ISNUMBER(INDIRECT("'"&RepPrefix6&"- Conversion'!J4:J202")),--(INDIRECT("'"&RepPrefix6&"- Conversion'!J4:J202")<TODAY()),--(INDIRECT("'"&RepPrefix6&"- Conversion'!G4:G202")="Opportunity Creation"))+SUMPRODUCT(--ISNUMBER(INDIRECT("'"&RepPrefix6&"- Conversion'!J4:J202")),--(INDIRECT("'"&RepPrefix6&"- Conversion'!J4:J202")<TODAY()),--(INDIRECT("'"&RepPrefix6&"- Conversion'!G4:G202")="Scoping"))+SUMPRODUCT(--ISNUMBER(INDIRECT("'"&RepPrefix6&"- Conversion'!J4:J202")),--(INDIRECT("'"&RepPrefix6&"- Conversion'!J4:J202")<TODAY()),--(INDIRECT("'"&RepPrefix6&"- Conversion'!G4:G202")="BOM Submission"))+SUMPRODUCT(--ISNUMBER(INDIRECT("'"&RepPrefix6&"- Conversion'!J4:J202")),--(INDIRECT("'"&RepPrefix6&"- Conversion'!J4:J202")<TODAY()),--(INDIRECT("'"&RepPrefix6&"- Conversion'!G4:G202")="Resubmission"))+SUMPRODUCT(--ISNUMBER(INDIRECT("'"&RepPrefix6&"- Conversion'!J4:J202")),--(INDIRECT("'"&RepPrefix6&"- Conversion'!J4:J202")<TODAY()),--(INDIRECT("'"&RepPrefix6&"- Conversion'!G4:G202")="Negotiation"))),0))))
B11: TOTAL | C11: =SUM(C5:C10) | D11: =SUM(D5:D10) | E11: =SUM(E5:E10) | F11: =SUM(F5:F10) | G11: =IFERROR(SUM(E5:E10)/(SUM(E5:E10)+SUM(F5:F10)),0) | H11: =SUM(H5:H10) | I11: =SUM(I5:I10) | J11: =IFERROR(I11/H11,0) | K11: =SUM(K5:K10) | L11: =IFERROR(H11/(D11+E11),0) | M11: =SUM(M5:M10)

Sheet Stage Funnel
B2: STAGE FUNNEL · PIPELINE BY STAGE
B4: STAGE | C4: Probability | D4: =RepName1&" #" | E4: =RepName2&" #" | F4: =RepName3&" #" | G4: =IF(RepPrefix4="","—",RepName4&" #") | H4: =IF(RepPrefix5="","—",RepName5&" #") | I4: =IF(RepPrefix6="","—",RepName6&" #") | J4: Total Opps | K4: Total TCV | L4: Weighted
B5: Opportunity Creation | C5: 0.1 | D5: =COUNTIF('Madine- Conversion'!G4:G202,"Opportunity Creation") | E5: =COUNTIF('Zarrah-Conversion'!G3:G201,"Opportunity Creation") | F5: =COUNTIF('Home-Conversion'!G4:G202,"Opportunity Creation") | G5: =IF(RepPrefix4="","",IF(RepPrefix4="",0,IFERROR(COUNTIF(INDIRECT("'"&RepPrefix4&"- Conversion'!G4:G202"),"Opportunity Creation"),0))) | H5: =IF(RepPrefix5="","",IF(RepPrefix5="",0,IFERROR(COUNTIF(INDIRECT("'"&RepPrefix5&"- Conversion'!G4:G202"),"Opportunity Creation"),0))) | I5: =IF(RepPrefix6="","",IF(RepPrefix6="",0,IFERROR(COUNTIF(INDIRECT("'"&RepPrefix6&"- Conversion'!G4:G202"),"Opportunity Creation"),0))) | J5: =SUM(D5:I5) | K5: =SUMIFS('Madine- Conversion'!H4:H202,'Madine- Conversion'!G4:G202,"Opportunity Creation")+SUMIFS('Zarrah-Conversion'!H3:H201,'Zarrah-Conversion'!G3:G201,"Opportunity Creation")+SUMIFS('Home-Conversion'!H4:H202,'Home-Conversion'!G4:G202,"Opportunity Creation")+IF(RepPrefix4="",0,IFERROR(SUMIFS(INDIRECT("'"&RepPrefix4&"- Conversion'!H4:H202"),INDIRECT("'"&RepPrefix4&"- Conversion'!G4:G202"),"Opportunity Creation"),0))+IF(RepPrefix5="",0,IFERROR(SUMIFS(INDIRECT("'"&RepPrefix5&"- Conversion'!H4:H202"),INDIRECT("'"&RepPrefix5&"- Conversion'!G4:G202"),"Opportunity Creation"),0))+IF(RepPrefix6="",0,IFERROR(SUMIFS(INDIRECT("'"&RepPrefix6&"- Conversion'!H4:H202"),INDIRECT("'"&RepPrefix6&"- Conversion'!G4:G202"),"Opportunity Creation"),0)) | L5: =K5*C5
B6: Scoping | C6: 0.3 | D6: =COUNTIF('Madine- Conversion'!G4:G202,"Scoping") | E6: =COUNTIF('Zarrah-Conversion'!G3:G201,"Scoping") | F6: =COUNTIF('Home-Conversion'!G4:G202,"Scoping") | G6: =IF(RepPrefix4="","",IF(RepPrefix4="",0,IFERROR(COUNTIF(INDIRECT("'"&RepPrefix4&"- Conversion'!G4:G202"),"Scoping"),0))) | H6: =IF(RepPrefix5="","",IF(RepPrefix5="",0,IFERROR(COUNTIF(INDIRECT("'"&RepPrefix5&"- Conversion'!G4:G202"),"Scoping"),0))) | I6: =IF(RepPrefix6="","",IF(RepPrefix6="",0,IFERROR(COUNTIF(INDIRECT("'"&RepPrefix6&"- Conversion'!G4:G202"),"Scoping"),0))) | J6: =SUM(D6:I6) | K6: =SUMIFS('Madine- Conversion'!H4:H202,'Madine- Conversion'!G4:G202,"Scoping")+SUMIFS('Zarrah-Conversion'!H3:H201,'Zarrah-Conversion'!G3:G201,"Scoping")+SUMIFS('Home-Conversion'!H4:H202,'Home-Conversion'!G4:G202,"Scoping")+IF(RepPrefix4="",0,IFERROR(SUMIFS(INDIRECT("'"&RepPrefix4&"- Conversion'!H4:H202"),INDIRECT("'"&RepPrefix4&"- Conversion'!G4:G202"),"Scoping"),0))+IF(RepPrefix5="",0,IFERROR(SUMIFS(INDIRECT("'"&RepPrefix5&"- Conversion'!H4:H202"),INDIRECT("'"&RepPrefix5&"- Conversion'!G4:G202"),"Scoping"),0))+IF(RepPrefix6="",0,IFERROR(SUMIFS(INDIRECT("'"&RepPrefix6&"- Conversion'!H4:H202"),INDIRECT("'"&RepPrefix6&"- Conversion'!G4:G202"),"Scoping"),0)) | L6: =K6*C6
B7: BOM Submission | C7: 0.5 | D7: =COUNTIF('Madine- Conversion'!G4:G202,"BOM Submission") | E7: =COUNTIF('Zarrah-Conversion'!G3:G201,"BOM Submission") | F7: =COUNTIF('Home-Conversion'!G4:G202,"BOM Submission") | G7: =IF(RepPrefix4="","",IF(RepPrefix4="",0,IFERROR(COUNTIF(INDIRECT("'"&RepPrefix4&"- Conversion'!G4:G202"),"BOM Submission"),0))) | H7: =IF(RepPrefix5="","",IF(RepPrefix5="",0,IFERROR(COUNTIF(INDIRECT("'"&RepPrefix5&"- Conversion'!G4:G202"),"BOM Submission"),0))) | I7: =IF(RepPrefix6="","",IF(RepPrefix6="",0,IFERROR(COUNTIF(INDIRECT("'"&RepPrefix6&"- Conversion'!G4:G202"),"BOM Submission"),0))) | J7: =SUM(D7:I7) | K7: =SUMIFS('Madine- Conversion'!H4:H202,'Madine- Conversion'!G4:G202,"BOM Submission")+SUMIFS('Zarrah-Conversion'!H3:H201,'Zarrah-Conversion'!G3:G201,"BOM Submission")+SUMIFS('Home-Conversion'!H4:H202,'Home-Conversion'!G4:G202,"BOM Submission")+IF(RepPrefix4="",0,IFERROR(SUMIFS(INDIRECT("'"&RepPrefix4&"- Conversion'!H4:H202"),INDIRECT("'"&RepPrefix4&"- Conversion'!G4:G202"),"BOM Submission"),0))+IF(RepPrefix5="",0,IFERROR(SUMIFS(INDIRECT("'"&RepPrefix5&"- Conversion'!H4:H202"),INDIRECT("'"&RepPrefix5&"- Conversion'!G4:G202"),"BOM Submission"),0))+IF(RepPrefix6="",0,IFERROR(SUMIFS(INDIRECT("'"&RepPrefix6&"- Conversion'!H4:H202"),INDIRECT("'"&RepPrefix6&"- Conversion'!G4:G202"),"BOM Submission"),0)) | L7: =K7*C7
B8: Resubmission | C8: 0.7 | D8: =COUNTIF('Madine- Conversion'!G4:G202,"Resubmission") | E8: =COUNTIF('Zarrah-Conversion'!G3:G201,"Resubmission") | F8: =COUNTIF('Home-Conversion'!G4:G202,"Resubmission") | G8: =IF(RepPrefix4="","",IF(RepPrefix4="",0,IFERROR(COUNTIF(INDIRECT("'"&RepPrefix4&"- Conversion'!G4:G202"),"Resubmission"),0))) | H8: =IF(RepPrefix5="","",IF(RepPrefix5="",0,IFERROR(COUNTIF(INDIRECT("'"&RepPrefix5&"- Conversion'!G4:G202"),"Resubmission"),0))) | I8: =IF(RepPrefix6="","",IF(RepPrefix6="",0,IFERROR(COUNTIF(INDIRECT("'"&RepPrefix6&"- Conversion'!G4:G202"),"Resubmission"),0))) | J8: =SUM(D8:I8) | K8: =SUMIFS('Madine- Conversion'!H4:H202,'Madine- Conversion'!G4:G202,"Resubmission")+SUMIFS('Zarrah-Conversion'!H3:H201,'Zarrah-Conversion'!G3:G201,"Resubmission")+SUMIFS('Home-Conversion'!H4:H202,'Home-Conversion'!G4:G202,"Resubmission")+IF(RepPrefix4="",0,IFERROR(SUMIFS(INDIRECT("'"&RepPrefix4&"- Conversion'!H4:H202"),INDIRECT("'"&RepPrefix4&"- Conversion'!G4:G202"),"Resubmission"),0))+IF(RepPrefix5="",0,IFERROR(SUMIFS(INDIRECT("'"&RepPrefix5&"- Conversion'!H4:H202"),INDIRECT("'"&RepPrefix5&"- Conversion'!G4:G202"),"Resubmission"),0))+IF(RepPrefix6="",0,IFERROR(SUMIFS(INDIRECT("'"&RepPrefix6&"- Conversion'!H4:H202"),INDIRECT("'"&RepPrefix6&"- Conversion'!G4:G202"),"Resubmission"),0)) | L8: =K8*C8
B9: Negotiation | C9: 0.9 | D9: =COUNTIF('Madine- Conversion'!G4:G202,"Negotiation") | E9: =COUNTIF('Zarrah-Conversion'!G3:G201,"Negotiation") | F9: =COUNTIF('Home-Conversion'!G4:G202,"Negotiation") | G9: =IF(RepPrefix4="","",IF(RepPrefix4="",0,IFERROR(COUNTIF(INDIRECT("'"&RepPrefix4&"- Conversion'!G4:G202"),"Negotiation"),0))) | H9: =IF(RepPrefix5="","",IF(RepPrefix5="",0,IFERROR(COUNTIF(INDIRECT("'"&RepPrefix5&"- Conversion'!G4:G202"),"Negotiation"),0))) | I9: =IF(RepPrefix6="","",IF(RepPrefix6="",0,IFERROR(COUNTIF(INDIRECT("'"&RepPrefix6&"- Conversion'!G4:G202"),"Negotiation"),0))) | J9: =SUM(D9:I9) | K9: =SUMIFS('Madine- Conversion'!H4:H202,'Madine- Conversion'!G4:G202,"Negotiation")+SUMIFS('Zarrah-Conversion'!H3:H201,'Zarrah-Conversion'!G3:G201,"Negotiation")+SUMIFS('Home-Conversion'!H4:H202,'Home-Conversion'!G4:G202,"Negotiation")+IF(RepPrefix4="",0,IFERROR(SUMIFS(INDIRECT("'"&RepPrefix4&"- Conversion'!H4:H202"),INDIRECT("'"&RepPrefix4&"- Conversion'!G4:G202"),"Negotiation"),0))+IF(RepPrefix5="",0,IFERROR(SUMIFS(INDIRECT("'"&RepPrefix5&"- Conversion'!H4:H202"),INDIRECT("'"&RepPrefix5&"- Conversion'!G4:G202"),"Negotiation"),0))+IF(RepPrefix6="",0,IFERROR(SUMIFS(INDIRECT("'"&RepPrefix6&"- Conversion'!H4:H202"),INDIRECT("'"&RepPrefix6&"- Conversion'!G4:G202"),"Negotiation"),0)) | L9: =K9*C9
B10: Closed Won | C10: 1 | D10: =COUNTIF('Madine- Conversion'!G4:G202,"Closed Won") | E10: =COUNTIF('Zarrah-Conversion'!G3:G201,"Closed Won") | F10: =COUNTIF('Home-Conversion'!G4:G202,"Closed Won") | G10: =IF(RepPrefix4="","",IF(RepPrefix4="",0,IFERROR(COUNTIF(INDIRECT("'"&RepPrefix4&"- Conversion'!G4:G202"),"Closed Won"),0))) | H10: =IF(RepPrefix5="","",IF(RepPrefix5="",0,IFERROR(COUNTIF(INDIRECT("'"&RepPrefix5&"- Conversion'!G4:G202"),"Closed Won"),0))) | I10: =IF(RepPrefix6="","",IF(RepPrefix6="",0,IFERROR(COUNTIF(INDIRECT("'"&RepPrefix6&"- Conversion'!G4:G202"),"Closed Won"),0))) | J10: =SUM(D10:I10) | K10: =SUMIFS('Madine- Conversion'!H4:H202,'Madine- Conversion'!G4:G202,"Closed Won")+SUMIFS('Zarrah-Conversion'!H3:H201,'Zarrah-Conversion'!G3:G201,"Closed Won")+SUMIFS('Home-Conversion'!H4:H202,'Home-Conversion'!G4:G202,"Closed Won")+IF(RepPrefix4="",0,IFERROR(SUMIFS(INDIRECT("'"&RepPrefix4&"- Conversion'!H4:H202"),INDIRECT("'"&RepPrefix4&"- Conversion'!G4:G202"),"Closed Won"),0))+IF(RepPrefix5="",0,IFERROR(SUMIFS(INDIRECT("'"&RepPrefix5&"- Conversion'!H4:H202"),INDIRECT("'"&RepPrefix5&"- Conversion'!G4:G202"),"Closed Won"),0))+IF(RepPrefix6="",0,IFERROR(SUMIFS(INDIRECT("'"&RepPrefix6&"- Conversion'!H4:H202"),INDIRECT("'"&RepPrefix6&"- Conversion'!G4:G202"),"Closed Won"),0)) | L10: =K10*C10
B11: Closed Lost | C11: 0 | D11: =COUNTIF('Madine- Conversion'!G4:G202,"Closed Lost") | E11: =COUNTIF('Zarrah-Conversion'!G3:G201,"Closed Lost") | F11: =COUNTIF('Home-Conversion'!G4:G202,"Closed Lost") | G11: =IF(RepPrefix4="","",IF(RepPrefix4="",0,IFERROR(COUNTIF(INDIRECT("'"&RepPrefix4&"- Conversion'!G4:G202"),"Closed Lost"),0))) | H11: =IF(RepPrefix5="","",IF(RepPrefix5="",0,IFERROR(COUNTIF(INDIRECT("'"&RepPrefix5&"- Conversion'!G4:G202"),"Closed Lost"),0))) | I11: =IF(RepPrefix6="","",IF(RepPrefix6="",0,IFERROR(COUNTIF(INDIRECT("'"&RepPrefix6&"- Conversion'!G4:G202"),"Closed Lost"),0))) | J11: =SUM(D11:I11) | K11: =SUMIFS('Madine- Conversion'!H4:H202,'Madine- Conversion'!G4:G202,"Closed Lost")+SUMIFS('Zarrah-Conversion'!H3:H201,'Zarrah-Conversion'!G3:G201,"Closed Lost")+SUMIFS('Home-Conversion'!H4:H202,'Home-Conversion'!G4:G202,"Closed Lost")+IF(RepPrefix4="",0,IFERROR(SUMIFS(INDIRECT("'"&RepPrefix4&"- Conversion'!H4:H202"),INDIRECT("'"&RepPrefix4&"- Conversion'!G4:G202"),"Closed Lost"),0))+IF(RepPrefix5="",0,IFERROR(SUMIFS(INDIRECT("'"&RepPrefix5&"- Conversion'!H4:H202"),INDIRECT("'"&RepPrefix5&"- Conversion'!G4:G202"),"Closed Lost"),0))+IF(RepPrefix6="",0,IFERROR(SUMIFS(INDIRECT("'"&RepPrefix6&"- Conversion'!H4:H202"),INDIRECT("'"&RepPrefix6&"- Conversion'!G4:G202"),"Closed Lost"),0)) | L11: =K11*C11
B12: PIPELINE TOTAL (excl. Lost) | D12: =SUM(D5:D10) | E12: =SUM(E5:E10) | F12: =SUM(F5:F10) | G12: =SUM(G5:G10) | H12: =SUM(H5:H10) | I12: =SUM(I5:I10) | J12: =SUM(J5:J10) | K12: =SUM(K5:K10) | L12: =SUM(L5:L10)

Sheet Pipeline Health
B2: PIPELINE HEALTH · TOP DEALS & AT-RISK
B4: ACCOUNT | C4: REP | D4: STAGE | E4: TCV | F4: GP | G4: CLOSING | H4: FLAG | I4: NOTES
B5: =IFERROR(INDEX('Home-Conversion'!D4:D202,MATCH(LARGE('Home-Conversion'!T4:T202,1),'Home-Conversion'!T4:T202,0)),"") | C5: =IF(B5="","",RepName3) | D5: =IFERROR(INDEX('Home-Conversion'!G4:G202,MATCH(LARGE('Home-Conversion'!T4:T202,1),'Home-Conversion'!T4:T202,0)),"") | E5: =IFERROR(LARGE('Home-Conversion'!T4:T202,1),"") | F5: =IFERROR(INDEX('Home-Conversion'!I4:I202,MATCH(LARGE('Home-Conversion'!T4:T202,1),'Home-Conversion'!T4:T202,0)),"") | G5: =IFERROR(INDEX('Home-Conversion'!J4:J202,MATCH(LARGE('Home-Conversion'!T4:T202,1),'Home-Conversion'!T4:T202,0)),"") | H5: =IF(B5="","",IF(D5="Closed Won","✓ WON",IF(D5="Closed Lost","✗ LOST",IF(AND(G5<>"",ISNUMBER(G5),G5<TODAY()),"⚠ PAST DUE",IF(G5="","◔ NO DATE",IF(D5="Negotiation","● NEGOTIATING","○ ACTIVE"))))))
B6: =IFERROR(INDEX('Home-Conversion'!D4:D202,MATCH(LARGE('Home-Conversion'!T4:T202,2),'Home-Conversion'!T4:T202,0)),"") | C6: =IF(B6="","",RepName3) | D6: =IFERROR(INDEX('Home-Conversion'!G4:G202,MATCH(LARGE('Home-Conversion'!T4:T202,2),'Home-Conversion'!T4:T202,0)),"") | E6: =IFERROR(LARGE('Home-Conversion'!T4:T202,2),"") | F6: =IFERROR(INDEX('Home-Conversion'!I4:I202,MATCH(LARGE('Home-Conversion'!T4:T202,2),'Home-Conversion'!T4:T202,0)),"") | G6: =IFERROR(INDEX('Home-Conversion'!J4:J202,MATCH(LARGE('Home-Conversion'!T4:T202,2),'Home-Conversion'!T4:T202,0)),"") | H6: =IF(B6="","",IF(D6="Closed Won","✓ WON",IF(D6="Closed Lost","✗ LOST",IF(AND(G6<>"",ISNUMBER(G6),G6<TODAY()),"⚠ PAST DUE",IF(G6="","◔ NO DATE",IF(D6="Negotiation","● NEGOTIATING","○ ACTIVE"))))))
B7: =IFERROR(INDEX('Home-Conversion'!D4:D202,MATCH(LARGE('Home-Conversion'!T4:T202,3),'Home-Conversion'!T4:T202,0)),"") | C7: =IF(B7="","",RepName3) | D7: =IFERROR(INDEX('Home-Conversion'!G4:G202,MATCH(LARGE('Home-Conversion'!T4:T202,3),'Home-Conversion'!T4:T202,0)),"") | E7: =IFERROR(LARGE('Home-Conversion'!T4:T202,3),"") | F7: =IFERROR(INDEX('Home-Conversion'!I4:I202,MATCH(LARGE('Home-Conversion'!T4:T202,3),'Home-Conversion'!T4:T202,0)),"") | G7: =IFERROR(INDEX('Home-Conversion'!J4:J202,MATCH(LARGE('Home-Conversion'!T4:T202,3),'Home-Conversion'!T4:T202,0)),"") | H7: =IF(B7="","",IF(D7="Closed Won","✓ WON",IF(D7="Closed Lost","✗ LOST",IF(AND(G7<>"",ISNUMBER(G7),G7<TODAY()),"⚠ PAST DUE",IF(G7="","◔ NO DATE",IF(D7="Negotiation","● NEGOTIATING","○ ACTIVE"))))))
B8: =IFERROR(INDEX('Home-Conversion'!D4:D202,MATCH(LARGE('Home-Conversion'!T4:T202,4),'Home-Conversion'!T4:T202,0)),"") | C8: =IF(B8="","",RepName3) | D8: =IFERROR(INDEX('Home-Conversion'!G4:G202,MATCH(LARGE('Home-Conversion'!T4:T202,4),'Home-Conversion'!T4:T202,0)),"") | E8: =IFERROR(LARGE('Home-Conversion'!T4:T202,4),"") | F8: =IFERROR(INDEX('Home-Conversion'!I4:I202,MATCH(LARGE('Home-Conversion'!T4:T202,4),'Home-Conversion'!T4:T202,0)),"") | G8: =IFERROR(INDEX('Home-Conversion'!J4:J202,MATCH(LARGE('Home-Conversion'!T4:T202,4),'Home-Conversion'!T4:T202,0)),"") | H8: =IF(B8="","",IF(D8="Closed Won","✓ WON",IF(D8="Closed Lost","✗ LOST",IF(AND(G8<>"",ISNUMBER(G8),G8<TODAY()),"⚠ PAST DUE",IF(G8="","◔ NO DATE",IF(D8="Negotiation","● NEGOTIATING","○ ACTIVE"))))))
B9: =IFERROR(INDEX('Home-Conversion'!D4:D202,MATCH(LARGE('Home-Conversion'!T4:T202,5),'Home-Conversion'!T4:T202,0)),"") | C9: =IF(B9="","",RepName3) | D9: =IFERROR(INDEX('Home-Conversion'!G4:G202,MATCH(LARGE('Home-Conversion'!T4:T202,5),'Home-Conversion'!T4:T202,0)),"") | E9: =IFERROR(LARGE('Home-Conversion'!T4:T202,5),"") | F9: =IFERROR(INDEX('Home-Conversion'!I4:I202,MATCH(LARGE('Home-Conversion'!T4:T202,5),'Home-Conversion'!T4:T202,0)),"") | G9: =IFERROR(INDEX('Home-Conversion'!J4:J202,MATCH(LARGE('Home-Conversion'!T4:T202,5),'Home-Conversion'!T4:T202,0)),"") | H9: =IF(B9="","",IF(D9="Closed Won","✓ WON",IF(D9="Closed Lost","✗ LOST",IF(AND(G9<>"",ISNUMBER(G9),G9<TODAY()),"⚠ PAST DUE",IF(G9="","◔ NO DATE",IF(D9="Negotiation","● NEGOTIATING","○ ACTIVE"))))))
B10: =IFERROR(INDEX('Home-Conversion'!D4:D202,MATCH(LARGE('Home-Conversion'!T4:T202,6),'Home-Conversion'!T4:T202,0)),"") | C10: =IF(B10="","",RepName3) | D10: =IFERROR(INDEX('Home-Conversion'!G4:G202,MATCH(LARGE('Home-Conversion'!T4:T202,6),'Home-Conversion'!T4:T202,0)),"") | E10: =IFERROR(LARGE('Home-Conversion'!T4:T202,6),"") | F10: =IFERROR(INDEX('Home-Conversion'!I4:I202,MATCH(LARGE('Home-Conversion'!T4:T202,6),'Home-Conversion'!T4:T202,0)),"") | G10: =IFERROR(INDEX('Home-Conversion'!J4:J202,MATCH(LARGE('Home-Conversion'!T4:T202,6),'Home-Conversion'!T4:T202,0)),"") | H10: =IF(B10="","",IF(D10="Closed Won","✓ WON",IF(D10="Closed Lost","✗ LOST",IF(AND(G10<>"",ISNUMBER(G10),G10<TODAY()),"⚠ PAST DUE",IF(G10="","◔ NO DATE",IF(D10="Negotiation","● NEGOTIATING","○ ACTIVE"))))))
